Workbook

Sheet settings
A1: key | B1: value | C1: notes
A2: base_year | B2: 2024 | C2: Base (reference) year for stock and calibration
A3: discount_rate | B3: 0.07 | C3: Annual social discount rate [fraction]
A4: cost_unit | B4: cr. INR | C4: Model output cost unit (crore Indian Rupees)
A5: cost_unit_alt | B5: MUSD | C5: Input data unit in Excel (million USD); reader converts using usd_to_crinr
A6: usd_to_inr | B6: 83.5 | C6: 1 USD = usd_to_inr INR — base year
A7: musd_to_crinr | B7: =B6/10 -> 8.35 | C7: 1 MUSD = usd_to_inr/10 cr. INR
A8: energy_unit | B8: PJ | C8: Energy unit (Petajoules)
A9: distance_unit | B9: km | C9: Distance unit
A10: capacity_unit | B10: 1000 vehicles | C10: Vehicle fleet capacity unit (1000 vehicles per unit)
A11: milestone_years | B11: 2025,2030,2035,2040,2045,2050 | C11: Model milestone years (comma-separated)
A12: calendar_name | B12: ANNUAL | C12: Timeslice resolution
A13: base_region | B13: IND | C13: Base region code

Sheet commodities
A1: name | B1: desc | C1: unit | D1: timeframe | E1: emis_CO2 | F1: emis_PM | G1: notes | H1: branch | I1: energy_content | J1: energy_unit
A2: GSL | B2: Gasoline (petrol) | C2: PJ | D2: ANNUAL | E2: 69.3 | G2: tCO2/PJ — source: EIA | H2: shared | I2: 34.2 | J2: MJ/L
A3: DSL | B3: Diesel | C3: PJ | D3: ANNUAL | E3: 74.1 | G3: tCO2/PJ — source: EIA | H3: shared | I3: 36.9 | J3: MJ/L
A4: BIO | B4: Biofuels (ethanol, biodiesel) | C4: PJ | D4: ANNUAL | E4: 0 | G4: Assumed carbon-neutral at combustion | H4: shared | I4: 26.8 | J4: MJ/L
A5: ELCPJ | B5: Electricity for transport | C5: PJ | D5: ANNUAL | E5: 0 | G5: No direct combustion emissions | H5: shared
A6: CNG | B6: Compressed Natural Gas | C6: PJ | D6: ANNUAL | E6: 56.1 | G6: tCO2/PJ — source: IEA/IPCC | H6: shared | I6: 35.8 | J6: MJ/m3 STP
A7: LPG | B7: Liquefied Petroleum Gas (Autogas) | C7: PJ | D7: ANNUAL | E7: 63.1 | G7: tCO2/PJ | H7: shared | I7: 26 | J7: MJ/L
A8: H2 | B8: Hydrogen (compressed, green/blue) | C8: PJ | D8: ANNUAL | E8: 0 | G8: Zero emission at point of use | H8: shared | I8: 120 | J8: MJ/kg
A9: GSL10 | B9: Blended fuel: 10% Ethanol + 90% Gasoline | C9: PJ | D9: ANNUAL | E9: 62.37 | G9: = 0.9 * GSL emission factor (10% bio blend) | H9: shared | I9: 32.9 | J9: MJ/L
A10: PLDVHWY | B10: LDV passengers — highway | C10: MPKm | D10: ANNUAL | G10: Final demand; unit = million passenger·km | H10: LDV_psgr
A11: PLDVCTY | B11: LDV passengers — city | C11: MPKm | D11: ANNUAL | G11: Final demand; unit = million passenger·km | H11: LDV_psgr
A12: FLDVHWY | B12: LDV freight — highway | C12: MTKm | D12: ANNUAL | G12: Final demand; unit = million tonne·km (LDV freight) | H12: LDV_frgt
A13: FLDVCTY | B13: LDV freight — city | C13: MTKm | D13: ANNUAL | G13: Final demand; unit = million tonne·km (LDV freight) | H13: LDV_frgt
A14: PETRO_REFUEL | B14: Petrol refueling station services | C14: PJ | D14: ANNUAL | G14: Auxiliary commodity for tech aeff (cap2ainp) | H14: infra
A15: CNG_REFUEL | B15: CNG refueling station services | C15: PJ | D15: ANNUAL | G15: Auxiliary commodity for tech aeff (cap2ainp) | H15: infra
A16: LPG_REFUEL | B16: LPG refueling station services | C16: PJ | D16: ANNUAL | G16: Auxiliary commodity for tech aeff (cap2ainp) | H16: infra
A17: EV_CHARGING | B17: EV charging station services | C17: GWh | D17: ANNUAL | G17: Auxiliary commodity for tech aeff (cap2ainp); GWh | H17: infra
A18: HPSGRHWY | B18: HDV passengers — highway | C18: MPKm | D18: ANNUAL | G18: Final demand; million passenger·km (buses) | H18: HDV_psgr
A19: HPSGRCTY | B19: HDV passengers — city | C19: MPKm | D19: ANNUAL | G19: Final demand; million passenger·km (buses) | H19: HDV_psgr
A20: HFRGTHWY | B20: HDV freight — highway | C20: MTKm | D20: ANNUAL | G20: Final demand; million tonne·km (trucks) | H20: HDV_frgt
A21: HFRGTCTY | B21: HDV freight — city | C21: MTKm | D21: ANNUAL | G21: Final demand; million tonne·km (trucks) | H21: HDV_frgt
... A39: CNG_LEAK | B39: Fugitive CNG/methane leakage from CNG refueling stations | C39: PJ | D39: ANNUAL | G39: Auxiliary output for INFR_CNG_REFUEL aeff act2aout=0.01. Add to GHG constraint later. | H39: infra

Sheet demand
A1: name | B1: desc | C1: commodity | D1: unit | E1: region | F1: y2025 | G1: y2030 | H1: y2035 | I1: y2040 | J1: y2045 | K1: y2050 | L1: notes | M1: branch
A2: DEM_PLDVHWY | B2: LDV passenger demand — highway | C2: PLDVHWY | D2: MPKm | E2: IND | F2: 158806 | G2: =F2*(1+demand_drivers!E2)^5 -> 190257.53 | H2: =G2*(1+demand_drivers!F2)^5 -> 223683.13 | I2: =H2*(1+demand_drivers!G2)^5 -> 270969.22 | J2: =I2*(1+demand_drivers!H2)^5 -> 335099.76 | K2: =J2*(1+demand_drivers!I2)^5 -> 427274.49 | L2: EPS: SYVbT_psgr × BAADTbVT × AVLo × 20% hwy. Calibrate from MoRTH/VAHAN. | M2: LDV_psgr
A3: DEM_PLDVCTY | B3: LDV passenger demand — city | C3: PLDVCTY | D3: MPKm | E3: IND | F3: 635224 | G3: =F3*(1+demand_drivers!E3)^5 -> 761030.11 | H3: =G3*(1+demand_drivers!F3)^5 -> 894732.53 | I3: =H3*(1+demand_drivers!G3)^5 -> 1083876.9 | J3: =I3*(1+demand_drivers!H3)^5 -> 1340399.1 | K3: =J3*(1+demand_drivers!I3)^5 -> 1709098 | L3: EPS: SYVbT_psgr × BAADTbVT × AVLo × 80% cty. Calibrate from MoRTH/VAHAN. | M3: LDV_psgr
A4: DEM_FLDVHWY | B4: LDV freight demand — highway | C4: FLDVHWY | D4: MTKm | E4: IND | F4: 59511 | G4: =F4*(1+demand_drivers!E4)^5 -> 71848.986 | H4: =G4*(1+demand_drivers!F4)^5 -> 85705.721 | I4: =H4*(1+demand_drivers!G4)^5 -> 101791.51 | J4: =I4*(1+demand_drivers!H4)^5 -> 120721.27 | K4: =J4*(1+demand_drivers!I4)^5 -> 143171.33 | L4: EPS: SYVbT_frgt × BAADTbVT_frgt × AVLo_frgt × 40% hwy. Calibrate from MoRTH. | M4: LDV_frgt
A5: DEM_FLDVCTY | B5: LDV freight demand — city | C5: FLDVCTY | D5: MTKm | E5: IND | F5: 89266 | G5: =F5*(1+demand_drivers!E5)^5 -> 107772.88 | H5: =G5*(1+demand_drivers!F5)^5 -> 128557.86 | I5: =H5*(1+demand_drivers!G5)^5 -> 152686.41 | J5: =I5*(1+demand_drivers!H5)^5 -> 181080.89 | K5: =J5*(1+demand_drivers!I5)^5 -> 214755.79 | L5: EPS: SYVbT_frgt × BAADTbVT_frgt × AVLo_frgt × 60% cty. Calibrate from MoRTH. | M5: LDV_frgt
A6: DEM_HPSGRHWY | B6: HDV passenger demand — highway | C6: HPSGRHWY | D6: MPKm | E6: IND | F6: 2103036 | G6: =F6*(1+demand_drivers!E6)^5 -> 2682788.2 | H6: =G6*(1+demand_drivers!F6)^5 -> 3308198 | I6: =H6*(1+demand_drivers!G6)^5 -> 3990218 | J6: =I6*(1+demand_drivers!H6)^5 -> 4759768 | K6: =J6*(1+demand_drivers!I6)^5 -> 5634020.3 | L6: EPS: SYVbT_psgr HDVs × BAADTbVT × AVLo_hdv × 30% hwy. | M6: HDV_psgr
A7: DEM_HPSGRCTY | B7: HDV passenger demand — city | C7: HPSGRCTY | D7: MPKm | E7: IND | F7: 4907084 | G7: =F7*(1+demand_drivers!E7)^5 -> 6259839.1 | H7: =G7*(1+demand_drivers!F7)^5 -> 7719128.7 | I7: =H7*(1+demand_drivers!G7)^5 -> 9310508.6 | J7: =I7*(1+demand_drivers!H7)^5 -> 11106125 | K7: =J7*(1+demand_drivers!I7)^5 -> 13146047 | L7: EPS: SYVbT_psgr HDVs × BAADTbVT × AVLo_hdv × 70% cty. | M7: HDV_psgr
A8: DEM_HFRGTHWY | B8: HDV freight demand — highway | C8: HFRGTHWY | D8: MTKm | E8: IND | F8: 938961 | G8: =F8*(1+demand_drivers!E8)^5 -> 1288270.9 | H8: =G8*(1+demand_drivers!F8)^5 -> 1741142.2 | I8: =H8*(1+demand_drivers!G8)^5 -> 2295082.3 | J8: =I8*(1+demand_drivers!H8)^5 -> 2962800.8 | K8: =J8*(1+demand_drivers!I8)^5 -> 3759809.6 | L8: EPS: SYVbT_frgt HDVs × BAADTbVT_frgt × AVLo_hdv_frgt × 60% hwy. | M8: HDV_frgt
A9: DEM_HFRGTCTY | B9: HDV freight demand — city | C9: HFRGTCTY | D9: MTKm | E9: IND | F9: 625974 | G9: =F9*(1+demand_drivers!E9)^5 -> 858847.25 | H9: =G9*(1+demand_drivers!F9)^5 -> 1160761.4 | I9: =H9*(1+demand_drivers!G9)^5 -> 1530054.8 | J9: =I9*(1+demand_drivers!H9)^5 -> 1975200.5 | K9: =J9*(1+demand_drivers!I9)^5 -> 2506539.7 | L9: EPS: SYVbT_frgt HDVs × BAADTbVT_frgt × AVLo_hdv_frgt × 40% cty. | M9: HDV_frgt
A10: DEM_APSGRINT | B10: aircraft psgr demand — INT | C10: APSGRINT | D10: MPKm | E10: IND | F10: 76836 | G10: =F10*(1+demand_drivers!E10)^5 -> 109234.79 | H10: =G10*(1+demand_drivers!F10)^5 -> 150294.57 | I10: =H10*(1+demand_drivers!G10)^5 -> 222472.68 | J10: =I10*(1+demand_drivers!H10)^5 -> 314662.83 | K10: =J10*(1+demand_drivers!I10)^5 -> 424677.3 | L10: EPS SYVbT x BAADTbVT x AVLo. Sector: aircraft | M10: aircraft_psgr
A11: DEM_APSGRDOM | B11: aircraft psgr demand — DOM | C11: APSGRDOM | D11: MPKm | E11: IND | F11: 32930 | G11: =F11*(1+demand_drivers!E11)^5 -> 46815.316 | H11: =G11*(1+demand_drivers!F11)^5 -> 64412.517 | I11: =H11*(1+demand_drivers!G11)^5 -> 95346.26 | J11: =I11*(1+demand_drivers!H11)^5 -> 134856.67 | K11: =J11*(1+demand_drivers!I11)^5 -> 182006.14 | L11: EPS SYVbT x BAADTbVT x AVLo. Sector: aircraft | M11: aircraft_psgr
A12: DEM_AFRGTINT | B12: aircraft frgt demand — INT | C12: AFRGTINT | D12: MTKm | E12: IND | F12: 499 | G12: =F12*(1+demand_drivers!E12)^5 -> 709.40913 | H12: =G12*(1+demand_drivers!F12)^5 -> 976.06577 | I12: =H12*(1+demand_drivers!G12)^5 -> 1444.8158 | J12: =I12*(1+demand_drivers!H12)^5 -> 2043.531 | K12: =J12*(1+demand_drivers!I12)^5 -> 2758.0037 | L12: EPS SYVbT x BAADTbVT x AVLo. Sector: aircraft | M12: aircraft_frgt
A13: DEM_AFRGTDOM | B13: aircraft frgt demand — DOM | C13: AFRGTDOM | D13: MTKm | E13: IND | F13: 166 | G13: =F13*(1+demand_drivers!E13)^5 -> 235.99582 | H13: =G13*(1+demand_drivers!F13)^5 -> 324.70324 | I13: =H13*(1+demand_drivers!G13)^5 -> 480.64012 | J13: =I13*(1+demand_drivers!H13)^5 -> 679.81193 | K13: =J13*(1+demand_drivers!I13)^5 -> 917.49221 | L13: EPS SYVbT x BAADTbVT x AVLo. Sector: aircraft | M13: aircraft_frgt
... A25: DEM_MFRGTCTY | B25: motorbikes frgt demand — CTY | C25: MFRGTCTY | D25: MTKm | E25: IND | F25: 210824 | G25: =F25*(1+demand_drivers!E25)^5 -> 251240.66 | H25: =G25*(1+demand_drivers!F25)^5 -> 299405.53 | I25: =H25*(1+demand_drivers!G25)^5 -> 356803.98 | J25: =I25*(1+demand_drivers!H25)^5 -> 425411.5 | K25: =J25*(1+demand_drivers!I25)^5 -> 507211.11 | L25: EPS SYVbT x BAADTbVT x AVLo. Sector: motorbikes | M25: motorbikes_frgt

Sheet demand_drivers
A1: demand_name | B1: scenario | C1: base_year | D1: base_year_value | E1: CAGR_to_2030 | F1: CAGR_to_2035 | G1: CAGR_to_2040 | H1: CAGR_to_2045 | I1: CAGR_to_2050 | J1: source | K1: notes | L1: branch
A2: DEM_PLDVHWY | B2: base | C2: 2025 | D2: 158806 | E2: 0.0368 | F2: 0.0329 | G2: 0.0391 | H2: 0.0434 | I2: 0.0498 | J2: EPS BCDTRtSY-psgr.csv, LDVs row (period CAGR from 2025 base) | K2: Edit CAGR values here to change demand projections. demand tab y-year columns contain formulas referencing these cells. | L2: LDV_psgr
A3: DEM_PLDVCTY | B3: base | C3: 2025 | D3: 635224 | E3: 0.0368 | F3: 0.0329 | G3: 0.0391 | H3: 0.0434 | I3: 0.0498 | J3: EPS BCDTRtSY-psgr.csv, LDVs row (period CAGR from 2025 base) | K3: Edit CAGR values here to change demand projections. demand tab y-year columns contain formulas referencing these cells. | L3: LDV_psgr
A4: DEM_FLDVHWY | B4: base | C4: 2025 | D4: 59511 | E4: 0.0384 | F4: 0.0359 | G4: 0.035 | H4: 0.0347 | I4: 0.0347 | J4: EPS BCDTRtSY-frgt.csv, LDVs row (period CAGR from 2025 base) | K4: Edit CAGR values here to change demand projections. demand tab y-year columns contain formulas referencing these cells. | L4: LDV_frgt
A5: DEM_FLDVCTY | B5: base | C5: 2025 | D5: 89266 | E5: 0.0384 | F5: 0.0359 | G5: 0.035 | H5: 0.0347 | I5: 0.0347 | J5: EPS BCDTRtSY-frgt.csv, LDVs row (period CAGR from 2025 base) | K5: Edit CAGR values here to change demand projections. demand tab y-year columns contain formulas referencing these cells. | L5: LDV_frgt
A6: DEM_HPSGRHWY | B6: base | C6: 2025 | D6: 2103036 | E6: 0.0499 | F6: 0.0428 | G6: 0.0382 | H6: 0.0359 | I6: 0.0343 | J6: EPS BCDTRtSY-psgr.csv, HDVs row (period CAGR from 2025 base) | K6: Edit CAGR values here to change demand projections. demand tab y-year columns contain formulas referencing these cells. | L6: HDV_psgr
A7: DEM_HPSGRCTY | B7: base | C7: 2025 | D7: 4907084 | E7: 0.0499 | F7: 0.0428 | G7: 0.0382 | H7: 0.0359 | I7: 0.0343 | J7: EPS BCDTRtSY-psgr.csv, HDVs row (period CAGR from 2025 base) | K7: Edit CAGR values here to change demand projections. demand tab y-year columns contain formulas referencing these cells. | L7: HDV_psgr
A8: DEM_HFRGTHWY | B8: base | C8: 2025 | D8: 938961 | E8: 0.0653 | F8: 0.0621 | G8: 0.0568 | H8: 0.0524 | I8: 0.0488 | J8: EPS BCDTRtSY-frgt.csv, HDVs row (period CAGR from 2025 base) | K8: Edit CAGR values here to change demand projections. demand tab y-year columns contain formulas referencing these cells. | L8: HDV_frgt
A9: DEM_HFRGTCTY | B9: base | C9: 2025 | D9: 625974 | E9: 0.0653 | F9: 0.0621 | G9: 0.0568 | H9: 0.0524 | I9: 0.0488 | J9: EPS BCDTRtSY-frgt.csv, HDVs row (period CAGR from 2025 base) | K9: Edit CAGR values here to change demand projections. demand tab y-year columns contain formulas referencing these cells. | L9: HDV_frgt
A10: DEM_APSGRINT | B10: base | C10: 2025 | D10: 76836 | E10: 0.0729 | F10: 0.0659 | G10: 0.0816 | H10: 0.0718 | I10: 0.0618 | J10: EPS BCDTRtSY, aircraft row | K10: Edit CAGR values here to change demand projections. | L10: aircraft_psgr
A11: DEM_APSGRDOM | B11: base | C11: 2025 | D11: 32930 | E11: 0.0729 | F11: 0.0659 | G11: 0.0816 | H11: 0.0718 | I11: 0.0618 | J11: EPS BCDTRtSY, aircraft row | K11: Edit CAGR values here to change demand projections. | L11: aircraft_psgr
A12: DEM_AFRGTINT | B12: base | C12: 2025 | D12: 499 | E12: 0.0729 | F12: 0.0659 | G12: 0.0816 | H12: 0.0718 | I12: 0.0618 | J12: EPS BCDTRtSY, aircraft row | K12: Edit CAGR values here to change demand projections. | L12: aircraft_frgt
A13: DEM_AFRGTDOM | B13: base | C13: 2025 | D13: 166 | E13: 0.0729 | F13: 0.0659 | G13: 0.0816 | H13: 0.0718 | I13: 0.0618 | J13: EPS BCDTRtSY, aircraft row | K13: Edit CAGR values here to change demand projections. | L13: aircraft_frgt
... A25: DEM_MFRGTCTY | B25: base | C25: 2025 | D25: 210824 | E25: 0.0357 | F25: 0.0357 | G25: 0.0357 | H25: 0.0358 | I25: 0.0358 | J25: EPS BCDTRtSY, motorbikes row | K25: Edit CAGR values here to change demand projections. | L25: motorbikes_frgt

Sheet supply
A1: name | B1: commodity | C1: region | D1: y2025 | E1: y2030 | F1: y2035 | G1: y2040 | H1: y2045 | I1: y2050 | J1: ava_up_PJ_2025 | K1: ava_up_PJ_2035 | L1: ava_up_PJ_2100 | M1: notes
A2: SUP_GSL | B2: GSL | C2: IND | D2: =supply_calcs!H2 -> 41.5 | E2: =Table7[[#This Row],[y2025]] -> 41.5 | F2: =Table7[[#This Row],[y2030]] -> 41.5 | G2: =Table7[[#This Row],[y2035]] -> 41.5 | H2: =Table7[[#This Row],[y2040]] -> 41.5 | I2: =Table7[[#This Row],[y2045]] -> 41.5 | J2: 2000 | K2: 5000 | L2: =Table7[[#This Row],[ava_up_PJ_2035]]*10 -> 50000 | M2: 2025 placeholder — MUSD/PJ. Source: transport.Rmd / LDV-passenger.Rmd
A3: SUP_DSL | B3: DSL | C3: IND | D3: =supply_calcs!H3 -> 35.76 | E3: =Table7[[#This Row],[y2025]] -> 35.76 | F3: =Table7[[#This Row],[y2030]] -> 35.76 | G3: =Table7[[#This Row],[y2035]] -> 35.76 | H3: =Table7[[#This Row],[y2040]] -> 35.76 | I3: =Table7[[#This Row],[y2045]] -> 35.76 | J3: 4000 | K3: 10000 | L3: =Table7[[#This Row],[ava_up_PJ_2035]]*10 -> 100000 | M3: 2025 placeholder — MUSD/PJ. Source: transport.Rmd / LDV-passenger.Rmd
A4: SUP_BIO | B4: BIO | C4: IND | D4: =supply_calcs!H4 -> 62.88 | E4: =Table7[[#This Row],[y2025]] -> 62.88 | F4: =Table7[[#This Row],[y2030]] -> 62.88 | G4: =Table7[[#This Row],[y2035]] -> 62.88 | H4: =Table7[[#This Row],[y2040]] -> 62.88 | I4: =Table7[[#This Row],[y2045]] -> 62.88 | J4: 500 | K4: 5000 | L4: =Table7[[#This Row],[ava_up_PJ_2035]]*10 -> 50000 | M4: 2025 placeholder — MUSD/PJ. Source: transport.Rmd / LDV-passenger.Rmd
A5: SUP_ELCPJ | B5: ELCPJ | C5: IND | D5: =supply_calcs!H5 -> 24.29 | E5: =Table7[[#This Row],[y2025]] -> 24.29 | F5: =Table7[[#This Row],[y2030]] -> 24.29 | G5: =Table7[[#This Row],[y2035]] -> 24.29 | H5: =Table7[[#This Row],[y2040]] -> 24.29 | I5: =Table7[[#This Row],[y2045]] -> 24.29 | J5: 1000 | K5: 10000 | L5: =Table7[[#This Row],[ava_up_PJ_2035]]*10 -> 100000 | M5: 2025 placeholder — MUSD/PJ. Source: transport.Rmd / LDV-passenger.Rmd
A6: SUP_CNG | B6: CNG | C6: IND | D6: =supply_calcs!H6 -> 23.71 | E6: =Table7[[#This Row],[y2025]] -> 23.71 | F6: =Table7[[#This Row],[y2030]] -> 23.71 | G6: =Table7[[#This Row],[y2035]] -> 23.71 | H6: =Table7[[#This Row],[y2040]] -> 23.71 | I6: =Table7[[#This Row],[y2045]] -> 23.71 | J6: 300 | K6: =J6*2 -> 600 | L6: =Table7[[#This Row],[ava_up_PJ_2035]]*10 -> 6000 | M6: 2025 placeholder — MUSD/PJ. Source: transport.Rmd / LDV-passenger.Rmd
A7: SUP_LPG | B7: LPG | C7: IND | D7: =supply_calcs!H7 -> 32.87 | E7: =Table7[[#This Row],[y2025]] -> 32.87 | F7: =Table7[[#This Row],[y2030]] -> 32.87 | G7: =Table7[[#This Row],[y2035]] -> 32.87 | H7: =Table7[[#This Row],[y2040]] -> 32.87 | I7: =Table7[[#This Row],[y2045]] -> 32.87 | J7: 1500 | K7: =J7*2 -> 3000 | L7: =Table7[[#This Row],[ava_up_PJ_2035]]*10 -> 30000 | M7: 2025 placeholder — MUSD/PJ. Source: transport.Rmd / LDV-passenger.Rmd
A8: SUP_H2 | B8: H2 | C8: IND | D8: 150 | E8: =Table7[[#This Row],[y2025]] -> 150 | F8: =Table7[[#This Row],[y2030]] -> 150 | G8: =Table7[[#This Row],[y2035]] -> 150 | H8: =Table7[[#This Row],[y2040]] -> 150 | I8: =Table7[[#This Row],[y2045]] -> 150 | J8: 10 | K8: 1000 | L8: =Table7[[#This Row],[ava_up_PJ_2035]]*10 -> 10000 | M8: 2025 placeholder — MUSD/PJ. Source: transport.Rmd / LDV-passenger.Rmd
A9: SUP_GSL10 | B9: GSL10 | C9: IND | D9: 50 | E9: =Table7[[#This Row],[y2025]] -> 50 | F9: =Table7[[#This Row],[y2030]] -> 50 | G9: =Table7[[#This Row],[y2035]] -> 50 | H9: =Table7[[#This Row],[y2040]] -> 50 | I9: =Table7[[#This Row],[y2045]] -> 50 | J9: 500 | K9: 2000 | L9: =Table7[[#This Row],[ava_up_PJ_2035]]*10 -> 20000 | M9: 2025 placeholder — MUSD/PJ. Source: transport.Rmd / LDV-passenger.Rmd

Sheet supply_calcs
B1: Price (Rs/ l)/ (Rs/kg)/ (Rs/kWh) | C1: Price in 2025 Rs | D1: LHV values (L/BTU) or (kg/BTU) | E1: Price (Rs/BTU) | F1: Price (Rs/kJ) | G1: Price (cr.₹/PJ) | H1: Price (MUSD/PJ) | I1: Notes | J1: Source
A2: GSL | B2: 105.01 | C2: =B2 -> 105.01 | D2: =3.3*10^-5 -> 3.3e-05 | E2: =C2*D2 -> 0.00346533 | F2: =E2*0.947817 -> 0.0032844987 | G2: =E2*100000 -> 346.533 | H2: =ROUND(G2/settings!$B$7, 2) -> 41.5 | I2: 2025 average price is taken | J2: Petrol Price in India: Year-Wise History From 1947 to 2026
A3: DSL | B3: 101.23 | C3: =B3 -> 101.23 | D3: =2.95*10^-5 -> 2.95e-05 | E3: =C3*D3 -> 0.002986285 | F3: =E3*0.947817 -> 0.0028304517 | G3: =E3*100000 -> 298.6285 | H3: =ROUND(G3/settings!$B$7, 2) -> 35.76 | I3: 2025 average price is taken | J3: Diesel Price In India: Yearly History From 2004 To 2026
A4: BIO | B4: =B2 -> 105.01 | C4: =C2 -> 105.01 | D4: =5*10^-5 -> 5e-05 | E4: =C4*D4 -> 0.0052505 | F4: =E4*0.947817 -> 0.0049765132 | G4: =E4*100000 -> 525.05 | H4: =ROUND(G4/settings!$B$7, 2) -> 62.88 | I4: Ethanol biofuel prices are same as Gasoline
A5: ELCPJ | B5: 6.92 | C5: =B5 -> 6.92 | D5: =1/3412 -> 0.00029308324 | E5: =C5*D5 -> 0.002028136 | F5: =E5*0.947817 -> 0.0019223018 | G5: =E5*100000 -> 202.8136 | H5: =ROUND(G5/settings!$B$7, 2) -> 24.29 | I5: EV charging station tariff (CSEP). Electricity prices range from Rs. 4 to Rs.13 per kWh depending on vehicle segment, location of charging etc. (CEEW). | J5: ceew-2-tco-annexure-28may25.pdf | K5: The-Fiscal-Impact-of-Indias-EV-Transition-Tax-Revenue-Losses-Go-Beyond-Fuel-2.pdf
A6: CNG | B6: 90 | C6: =B6 -> 90 | D6: =2.2*10^-5 -> 2.2e-05 | E6: =C6*D6 -> 0.00198 | F6: =E6*0.947817 -> 0.0018766777 | G6: =E6*100000 -> 198 | H6: =ROUND(G6/settings!$B$7, 2) -> 23.71 | I6: CNG price varies from 85 Rs/kg to 95 Rs/kg in 2025 | J6: CNG Price
A7: LPG | B7: 57 | C7: =B7*1.07 -> 60.99 | D7: =4.5*10^-5 -> 4.5e-05 | E7: =C7*D7 -> 0.00274455 | F7: =E7*0.947817 -> 0.0026013311 | G7: =E7*100000 -> 274.455 | H7: =ROUND(G7/settings!$B$7, 2) -> 32.87 | I7: LPG prices were around Rs 57/l in 2023 | J7: Auto LPG Stations in India : All States and Cities
A8: H2 | B8: 280 | C8: =B8 -> 280 | D8: =8.8*10^-6 -> 8.8e-06 | E8: =C8*D8 -> 0.002464 | F8: =E8*0.947817 -> 0.0023354211 | G8: =E8*100000 -> 246.4 | H8: =ROUND(G8/settings!$B$7, 2) -> 29.51 | I8: Rs 280 per kg, Based on 2026 tender for green hydrogen | J8: India hits lowest green hydrogen price, moves closer to $2/kg goal: Amitabh Kant, ETEnergyworld
A9: GSL10 | B9: =B2 -> 105.01 | C9: =C2 -> 105.01 | D9: =(0.1*D2)+(0.9*D4) -> 4.83e-05 | E9: =C9*D9 -> 0.005071983 | F9: =E9*0.947817 -> 0.0048073117 | G9: =E9*100000 -> 507.1983 | H9: =ROUND(G9/settings!$B$7, 2) -> 60.74

Sheet infrastructure
A1: name | B1: commodity | C1: region | D1: y2025 | E1: y2030 | F1: y2035 | G1: y2040 | H1: y2045 | I1: y2050 | J1: ava_up | K1: cost_unit | L1: notes
A2: SUP_PETRO_REFUEL | B2: PETRO_REFUEL | D2: 10 | K2: MUSD/PJ | L2: Placeholder — region=NA means model-wide. Used as auxiliary supply.
A3: SUP_CNG_REFUEL | B3: CNG_REFUEL | D3: 15 | K3: MUSD/PJ | L3: Placeholder — region=NA means model-wide. Used as auxiliary supply.
A4: SUP_LPG_REFUEL | B4: LPG_REFUEL | D4: 12 | K4: MUSD/PJ | L4: Placeholder — region=NA means model-wide. Used as auxiliary supply.
A5: SUP_EV_CHARGING | B5: EV_CHARGING | D5: 20 | K5: MUSD/GWh | L5: Placeholder — region=NA means model-wide. Used as auxiliary supply.

Sheet infra_tech
A1: name | B1: desc | C1: input_comm | D1: input_unit | E1: output_comm | F1: output_unit | G1: cap2act | H1: olife | I1: invcost_2025 | J1: fixom_2025 | K1: varom | L1: cng_leak | M1: cinp_comms | N1: cinp2ainp_ratio | O1: notes
A2: INFR_PETRO_REFUEL | B2: Petrol/diesel refueling station infrastructure | C2: LAND | D2: kha | E2: PETRO_REFUEL | F2: PJ | G2: 1 | H2: 50 | I2: 20 | J2: 2 | K2: 10 | M2: GSL,DSL,BIO | N2: 1 | O2: Petrol/diesel stations. varom covers retailer margin. GSL+DSL+BIO vehicles.
A3: INFR_CNG_REFUEL | B3: CNG compressor & refueling station infrastructure (with fugitive CH4 leakage) | C3: LAND | D3: kha | E3: CNG_REFUEL | F3: PJ | G3: 1 | H3: 50 | I3: 35 | J3: 3.5 | K3: 15 | L3: 0.01 | M3: CNG | N3: 1 | O3: CNG compressor stations. 1% fugitive CH4 via aeff act2aout=0.01 -> CNG_LEAK.
A4: INFR_LPG_REFUEL | B4: LPG autogas dispensing station infrastructure | C4: LAND | D4: kha | E4: LPG_REFUEL | F4: PJ | G4: 1 | H4: 50 | I4: 28 | J4: 2.8 | K4: 12 | M4: LPG | N4: 1 | O4: LPG autogas stations. Similar cost structure to petrol.
A5: INFR_EV_CHARGING | B5: EV charging station infrastructure (AC/DC mix) | C5: LAND | D5: kha | E5: EV_CHARGING | F5: GWh | G5: 1 | H5: 50 | I5: 30 | J5: 3 | K5: 5 | M5: ELCPJ | N5: 277.78 | O5: Public EV charging (AC + DC fast mix). Costs per GWh/yr of capacity.

Sheet technologies
A1: name | B1: desc | C1: fuels | D1: primary_fuel | E1: blend_fuel | F1: blend_share_up | G1: eff_hwy | H1: eff_cty | I1: eff_unit | J1: avg_km_yr | K1: capacity_units | L1: load_per_vehicle_hwy | M1: load_per_vehicle_cty | N1: share_hwy_up | O1: share_cty_up | P1: olife | Q1: region | R1: invcost_2025 | S1: invcost_2030 | T1: invcost_2035 | U1: invcost_2040 | V1: invcost_2045 | W1: invcost_2050 | X1: fixom_2025 | Y1: fixom_2030 | Z1: fixom_2035 | AA1: fixom_2040 | AB1: fixom_2045 | AC1: fixom_2050 | AD1: branch | AE1: service_hwy | AF1: service_cty | AG1: load_unit
A2: LDV_GSL | B2: Gasoline Light Duty Vehicle | C2: GSL | D2: GSL | G2: 4.3 | H2: 5.82 | I2: L/100km | J2: 12100 | K2: 1000 | L2: 2.03 | M2: 2.03 | N2: 0.4 | O2: 0.8 | P2: 16 | R2: 8414 | S2: 8414 | T2: 8414 | U2: 8414 | V2: 8414 | W2: 8414 | X2: 25 | Y2: 25 | Z2: 25 | AA2: 25 | AB2: 25 | AC2: 25 | AD2: LDV_psgr | AE2: PLDVHWY | AF2: PLDVCTY | AG2: passengers
A3: LDV_DSL | B3: Diesel Light Duty Vehicle | C3: DSL | D3: DSL | G3: 3.95 | H3: 5.35 | I3: L/100km | J3: 12100 | K3: 1000 | L3: 2.03 | M3: 2.03 | N3: 0.4 | O3: 0.8 | P3: 16 | R3: 11171 | S3: 11171 | T3: 11171 | U3: 11171 | V3: 11171 | W3: 11171 | X3: 25 | Y3: 25 | Z3: 25 | AA3: 25 | AB3: 25 | AC3: 25 | AD3: LDV_psgr | AE3: PLDVHWY | AF3: PLDVCTY | AG3: passengers
A4: LDV_E10 | B4: Gasoline–Ethanol Blend (E10) Light Duty Vehicle | C4: GSL|BIO | D4: GSL | E4: BIO | F4: 0.1 | G4: 4.3 | H4: 5.82 | I4: L/100km | J4: 12100 | K4: 1000 | L4: 2.03 | M4: 2.03 | N4: 0.4 | O4: 0.8 | P4: 16 | R4: 8414 | S4: 8414 | T4: 8414 | U4: 8414 | V4: 8414 | W4: 8414 | X4: 25 | Y4: 25 | Z4: 25 | AA4: 25 | AB4: 25 | AC4: 25 | AD4: LDV_psgr | AE4: PLDVHWY | AF4: PLDVCTY | AG4: passengers
A5: LDV_E85 | B5: E85 Flex-Fuel Light Duty Vehicle (85% Ethanol) | C5: GSL|BIO | D5: BIO | E5: GSL | F5: 0.15 | G5: 4.3 | H5: 5.82 | I5: L/100km | J5: 12100 | K5: 1000 | L5: 2.03 | M5: 2.03 | N5: 0.4 | O5: 0.8 | P5: 16 | R5: 8414 | S5: 8414 | T5: 8414 | U5: 8414 | V5: 8414 | W5: 8414 | X5: 25 | Y5: 25 | Z5: 25 | AA5: 25 | AB5: 25 | AC5: 25 | AD5: LDV_psgr | AE5: PLDVHWY | AF5: PLDVCTY | AG5: passengers
A6: LDV_E100 | B6: Pure Ethanol (E100) Light Duty Vehicle | C6: BIO | D6: BIO | G6: 4.3 | H6: 5.82 | I6: L/100km | J6: 12100 | K6: 1000 | L6: 2.03 | M6: 2.03 | N6: 0.4 | O6: 0.8 | P6: 16 | R6: 8414 | S6: 8414 | T6: 8414 | U6: 8414 | V6: 8414 | W6: 8414 | X6: 25 | Y6: 25 | Z6: 25 | AA6: 25 | AB6: 25 | AC6: 25 | AD6: LDV_psgr | AE6: PLDVHWY | AF6: PLDVCTY | AG6: passengers
A7: LDV_B100 | B7: Pure Biodiesel (B100) Light Duty Vehicle | C7: BIO | D7: BIO | G7: 3.95 | H7: 5.35 | I7: L/100km | J7: 12100 | K7: 1000 | L7: 2.03 | M7: 2.03 | N7: 0.4 | O7: 0.8 | P7: 16 | R7: 11171 | S7: 11171 | T7: 11171 | U7: 11171 | V7: 11171 | W7: 11171 | X7: 25 | Y7: 25 | Z7: 25 | AA7: 25 | AB7: 25 | AC7: 25 | AD7: LDV_psgr | AE7: PLDVHWY | AF7: PLDVCTY | AG7: passengers
A8: LDV_CNG | B8: Compressed Natural Gas Light Duty Vehicle | C8: CNG | D8: CNG | G8: 1.414 | H8: 1.914 | I8: MJ/km | J8: 12100 | K8: 1000 | L8: 2.03 | M8: 2.03 | N8: 0.4 | O8: 0.8 | P8: 16 | R8: 7677 | S8: 7677 | T8: 7677 | U8: 7677 | V8: 7677 | W8: 7677 | X8: 25 | Y8: 25 | Z8: 25 | AA8: 25 | AB8: 25 | AC8: 25 | AD8: LDV_psgr | AE8: PLDVHWY | AF8: PLDVCTY | AG8: passengers
A9: LDV_LPG | B9: LPG (Autogas) Light Duty Vehicle | C9: LPG | D9: LPG | G9: 1.414 | H9: 1.914 | I9: MJ/km | J9: 12100 | K9: 1000 | L9: 2.03 | M9: 2.03 | N9: 0.4 | O9: 0.8 | P9: 16 | R9: 4889 | S9: 4889 | T9: 4889 | U9: 4889 | V9: 4889 | W9: 4889 | X9: 25 | Y9: 25 | Z9: 25 | AA9: 25 | AB9: 25 | AC9: 25 | AD9: LDV_psgr | AE9: PLDVHWY | AF9: PLDVCTY | AG9: passengers
A10: LDV_HYB | B10: Gasoline Hybrid Light Duty Vehicle | C10: GSL | D10: GSL | G10: 4.3 | H10: 5.82 | I10: L/100km | J10: 12100 | K10: 1000 | L10: 2.03 | M10: 2.03 | N10: 0.4 | O10: 0.8 | P10: 16 | R10: 8414 | S10: 8414 | T10: 8414 | U10: 8414 | V10: 8414 | W10: 8414 | X10: 25 | Y10: 25 | Z10: 25 | AA10: 25 | AB10: 25 | AC10: 25 | AD10: LDV_psgr | AE10: PLDVHWY | AF10: PLDVCTY | AG10: passengers
A11: LDV_PHEV | B11: Plug-in Hybrid Light Duty Vehicle (combined cycle) | C11: GSL|ELCPJ | D11: GSL | G11: 2.67 | H11: 3.61 | I11: L/100km | J11: 12100 | K11: 1000 | L11: 2.03 | M11: 2.03 | N11: 0.4 | O11: 0.8 | P11: 16 | R11: 85108 | S11: 85108 | T11: 85108 | U11: 85108 | V11: 85108 | W11: 85108 | X11: 25 | Y11: 25 | Z11: 25 | AA11: 25 | AB11: 25 | AC11: 25 | AD11: LDV_psgr | AE11: PLDVHWY | AF11: PLDVCTY | AG11: passengers
A12: LDV_BEV | B12: Battery Electric Light Duty Vehicle | C12: ELCPJ | G12: 6.21 | H12: 7.59 | I12: km/kWh | J12: 12100 | K12: 1000 | L12: 2.03 | M12: 2.03 | N12: 0.4 | O12: 0.8 | P12: 16 | R12: 12098 | S12: 12098 | T12: 12098 | U12: 12098 | V12: 12098 | W12: 12098 | X12: 13 | Y12: 13 | Z12: 13 | AA12: 13 | AB12: 13 | AC12: 13 | AD12: LDV_psgr | AE12: PLDVHWY | AF12: PLDVCTY | AG12: passengers
A13: LDV_H2 | B13: Hydrogen Fuel Cell Light Duty Vehicle | C13: H2 | G13: 0.865 | H13: 1.171 | I13: MJ/km | J13: 12100 | K13: 1000 | L13: 2.03 | M13: 2.03 | N13: 0.4 | O13: 0.8 | P13: 16 | R13: 58916 | S13: 54715 | T13: 51322 | U13: 48453 | V13: 46196 | W13: 44402 | X13: 13 | Y13: 13 | Z13: 13 | AA13: 13 | AB13: 13 | AC13: 13 | AD13: LDV_psgr | AE13: PLDVHWY | AF13: PLDVCTY | AG13: passengers
A14: LDVF_DSL | B14: LDVF_DSL LDV_frgt vehicle | C14: DSL|BIO | D14: DSL | E14: BIO | F14: 0.2 | G14: 7.73 | H14: 10.46 | I14: L/100km | J14: 30000 | K14: 1000 | L14: 1.7 | M14: 1.7 | N14: 0.6 | O14: 0.9 | P14: 10 | R14: 6890 | S14: 6890 | T14: 6890 | U14: 6890 | V14: 6890 | W14: 6890 | X14: 25 | Y14: 25 | Z14: 25 | AA14: 25 | AB14: 25 | AC14: 25 | AD14: LDV_frgt | AE14: FLDVHWY | AF14: FLDVCTY | AG14: tonnes
A15: LDVF_CNG | B15: LDVF_CNG LDV_frgt vehicle | C15: CNG | D15: CNG | G15: 2.77 | H15: 3.748 | I15: MJ/km | J15: 30000 | K15: 1000 | L15: 1.7 | M15: 1.7 | N15: 0.6 | O15: 0.9 | P15: 10 | R15: 8851 | S15: 8851 | T15: 8851 | U15: 8851 | V15: 8851 | W15: 8851 | X15: 25 | Y15: 25 | Z15: 25 | AA15: 25 | AB15: 25 | AC15: 25 | AD15: LDV_frgt | AE15: FLDVHWY | AF15: FLDVCTY | AG15: tonnes
A16: LDVF_BEV | B16: LDVF_BEV LDV_frgt vehicle | C16: ELCPJ | D16: ELCPJ | G16: 3.17 | H16: 3.87 | I16: km/kWh | J16: 30000 | K16: 1000 | L16: 1.7 | M16: 1.7 | N16: 0.6 | O16: 0.9 | P16: 10 | R16: 9649 | S16: 9649 | T16: 9649 | U16: 9649 | V16: 9649 | W16: 9649 | X16: 13 | Y16: 13 | Z16: 13 | AA16: 13 | AB16: 13 | AC16: 13 | AD16: LDV_frgt | AE16: FLDVHWY | AF16: FLDVCTY | AG16: tonnes
A17: HDV_DSL | B17: HDV_DSL HDV_psgr vehicle | C17: DSL|BIO | D17: DSL | E17: BIO | F17: 0.2 | G17: 13.29 | H17: 17.99 | I17: L/100km | J17: 70000 | K17: 1000 | L17: 45 | M17: 45 | N17: 0.4 | O17: 0.9 | P17: 10 | R17: 35793 | S17: 35793 | T17: 35793 | U17: 35793 | V17: 35793 | W17: 35793 | X17: 96 | Y17: 96 | Z17: 96 | AA17: 96 | AB17: 96 | AC17: 96 | AD17: HDV_psgr | AE17: HPSGRHWY | AF17: HPSGRCTY | AG17: passengers
A18: HDV_CNG | B18: HDV_CNG HDV_psgr vehicle | C18: CNG | D18: CNG | G18: 4.758 | H18: 6.438 | I18: MJ/km | J18: 70000 | K18: 1000 | L18: 45 | M18: 45 | N18: 0.4 | O18: 0.9 | P18: 10 | R18: 47163 | S18: 47163 | T18: 47163 | U18: 47163 | V18: 47163 | W18: 47163 | X18: 96 | Y18: 96 | Z18: 96 | AA18: 96 | AB18: 96 | AC18: 96 | AD18: HDV_psgr | AE18: HPSGRHWY | AF18: HPSGRCTY | AG18: passengers
A19: HDV_BEV | B19: HDV_BEV HDV_psgr vehicle | C19: ELCPJ | D19: ELCPJ | G19: 1.84 | H19: 2.26 | I19: km/kWh | J19: 70000 | K19: 1000 | L19: 45 | M19: 45 | N19: 0.4 | O19: 0.9 | P19: 10 | R19: 216032 | S19: 216032 | T19: 216032 | U19: 216032 | V19: 216032 | W19: 216032 | X19: 76 | Y19: 76 | Z19: 76 | AA19: 76 | AB19: 76 | AC19: 76 | AD19: HDV_psgr | AE19: HPSGRHWY | AF19: HPSGRCTY | AG19: passengers
A20: HDVF_DSL | B20: HDVF_DSL HDV_frgt vehicle | C20: DSL|BIO | D20: DSL | E20: BIO | F20: 0.2 | G20: 18.05 | H20: 24.43 | I20: L/100km | J20: 50000 | K20: 1000 | L20: 6.1 | M20: 6.1 | N20: 0.7 | O20: 0.9 | P20: 10 | R20: 18344 | S20: 18344 | T20: 18344 | U20: 18344 | V20: 18344 | W20: 18344 | X20: 582 | Y20: 582 | Z20: 582 | AA20: 582 | AB20: 582 | AC20: 582 | AD20: HDV_frgt | AE20: HFRGTHWY | AF20: HFRGTCTY | AG20: tonnes
A21: HDVF_CNG | B21: HDVF_CNG HDV_frgt vehicle | C21: CNG | D21: CNG | G21: 6.463 | H21: 8.743 | I21: MJ/km | J21: 50000 | K21: 1000 | L21: 6.1 | M21: 6.1 | N21: 0.7 | O21: 0.9 | P21: 10 | R21: 17399 | S21: 17399 | T21: 17399 | U21: 17399 | V21: 17399 | W21: 17399 | X21: 582 | Y21: 582 | Z21: 582 | AA21: 582 | AB21: 582 | AC21: 582 | AD21: HDV_frgt | AE21: HFRGTHWY | AF21: HFRGTCTY | AG21: tonnes
A22: HDVF_BEV | B22: HDVF_BEV HDV_frgt vehicle | C22: ELCPJ | D22: ELCPJ | G22: 1.36 | H22: 1.66 | I22: km/kWh | J22: 50000 | K22: 1000 | L22: 6.1 | M22: 6.1 | N22: 0.7 | O22: 0.9 | P22: 10 | R22: 82298 | S22: 82298 | T22: 82298 | U22: 82298 | V22: 82298 | W22: 82298 | X22: 457 | Y22: 457 | Z22: 457 | AA22: 457 | AB22: 457 | AC22: 457 | AD22: HDV_frgt | AE22: HFRGTHWY | AF22: HFRGTCTY | AG22: tonnes
A23: ARC_DSL | B23: ARC_DSL aircraft_psgr vehicle | C23: DSL | D23: DSL | G23: 566.02 | H23: 765.78 | I23: L/100km | J23: 1106729 | K23: 1000 | L23: 180 | M23: 180 | N23: 0.85 | O23: 0.8 | P23: 20 | R23: 64833333 | S23: 64833333 | T23: 64833333 | U23: 64833333 | V23: 64833333 | W23: 64833333 | X23: 88399 | Y23: 88399 | Z23: 88399 | AA23: 88399 | AB23: 88399 | AC23: 88399 | AD23: aircraft_psgr | AE23: APSGRINT | AF23: APSGRDOM | AG23: passengers
A24: ARC_BEV | B24: ARC_BEV aircraft_psgr vehicle | C24: ELCPJ | D24: ELCPJ | G24: 0.03 | H24: 0.03 | I24: km/kWh | J24: 1106729 | K24: 1000 | L24: 180 | M24: 180 | N24: 0.85 | O24: 0.8 | P24: 20 | R24: 391303098 | S24: 391303098 | T24: 391303098 | U24: 391303098 | V24: 391303098 | W24: 391303098 | X24: 0 | Y24: 0 | Z24: 0 | AA24: 0 | AB24: 0 | AC24: 0 | AD24: aircraft_psgr | AE24: APSGRINT | AF24: APSGRDOM | AG24: passengers
A25: ARC_H2 | B25: ARC_H2 aircraft_psgr vehicle | C25: H2 | D25: H2 | G25: 81.026 | H25: 109.624 | I25: MJ/km | J25: 1106729 | K25: 1000 | L25: 180 | M25: 180 | N25: 0.85 | O25: 0.8 | P25: 20 | R25: 104999216 | S25: 97940564 | T25: 91917650 | U25: 86946207 | V25: 82736392 | W25: 79268162 | X25: 0 | Y25: 0 | Z25: 0 | AA25: 0 | AB25: 0 | AC25: 0 | AD25: aircraft_psgr | AE25: APSGRINT | AF25: APSGRDOM | AG25: passengers
A26: ARCF_DSL | B26: ARCF_DSL aircraft_frgt vehicle | C26: DSL | D26: DSL | G26: 196.01 | H26: 265.19 | I26: L/100km | J26: 567083 | K26: 1000 | L26: 17 | M26: 17 | N26: 0.9 | O26: 0.75 | P26: 32 | R26: 87319701 | S26: 87319701 | T26: 87319701 | U26: 87319701 | V26: 87319701 | W26: 87319701 | X26: 88399 | Y26: 88399 | Z26: 88399 | AA26: 88399 | AB26: 88399 | AC26: 88399 | AD26: aircraft_frgt | AE26: AFRGTINT | AF26: AFRGTDOM | AG26: tonnes
A27: ARCF_BEV | B27: ARCF_BEV aircraft_frgt vehicle | C27: ELCPJ | D27: ELCPJ | G27: 0.07 | H27: 0.09 | I27: km/kWh | J27: 567083 | K27: 1000 | L27: 17 | M27: 17 | N27: 0.9 | O27: 0.75 | P27: 32 | R27: 527020093 | S27: 527020093 | T27: 527020093 | U27: 527020093 | V27: 527020093 | W27: 527020093 | X27: 0 | Y27: 0 | Z27: 0 | AA27: 0 | AB27: 0 | AC27: 0 | AD27: aircraft_frgt | AE27: AFRGTINT | AF27: AFRGTDOM | AG27: tonnes
A28: ARCF_H2 | B28: ARCF_H2 aircraft_frgt vehicle | C28: H2 | D28: H2 | G28: 26.728 | H28: 36.162 | I28: MJ/km | J28: 567083 | K28: 1000 | L28: 17 | M28: 17 | N28: 0.9 | O28: 0.75 | P28: 32 | R28: 104999216 | S28: 97940564 | T28: 91917650 | U28: 86946207 | V28: 82736392 | W28: 79268162 | X28: 0 | Y28: 0 | Z28: 0 | AA28: 0 | AB28: 0 | AC28: 0 | AD28: aircraft_frgt | AE28: AFRGTINT | AF28: AFRGTDOM | AG28: tonnes
A29: RAIL_BEV | B29: RAIL_BEV rail_psgr vehicle | C29: ELCPJ | D29: ELCPJ | G29: 0.1 | H29: 0.12 | I29: km/kWh | J29: 232313 | K29: 1000 | L29: 1000 | M29: 1000 | N29: 0.75 | O29: 0.75 | P29: 35 | R29: 9830199 | S29: 9830199 | T29: 9830199 | U29: 9830199 | V29: 9830199 | W29: 9830199 | X29: 94402 | Y29: 94402 | Z29: 94402 | AA29: 94402 | AB29: 94402 | AC29: 94402 | AD29: rail_psgr | AE29: RPSGRICY | AF29: RPSGRLOC | AG29: passengers
A30: RAIL_DSL | B30: RAIL_DSL rail_psgr vehicle | C30: DSL | D30: DSL | G30: 149.67 | H30: 202.49 | I30: L/100km | J30: 232313 | K30: 1000 | L30: 1000 | M30: 1000 | N30: 0.75 | O30: 0.75 | P30: 35 | R30: 9282454 | S30: 9282454 | T30: 9282454 | U30: 9282454 | V30: 9282454 | W30: 9282454 | X30: 129230 | Y30: 129230 | Z30: 129230 | AA30: 129230 | AB30: 129230 | AC30: 129230 | AD30: rail_psgr | AE30: RPSGRICY | AF30: RPSGRLOC | AG30: passengers
A31: RAIL_H2 | B31: RAIL_H2 rail_psgr vehicle | C31: H2 | D31: H2 | G31: 261.681 | H31: 354.039 | I31: MJ/km | J31: 232313 | K31: 1000 | L31: 1000 | M31: 1000 | N31: 0.75 | O31: 0.75 | P31: 35 | R31: 4048813 | S31: 3776628 | T31: 3544382 | U31: 3352682 | V31: 3190349 | W31: 3056613 | X31: 94402 | Y31: 94402 | Z31: 94402 | AA31: 94402 | AB31: 94402 | AC31: 94402 | AD31: rail_psgr | AE31: RPSGRICY | AF31: RPSGRLOC | AG31: passengers
A32: RAILF_BEV | B32: RAILF_BEV rail_frgt vehicle | C32: ELCPJ | D32: ELCPJ | G32: 0.03 | H32: 0.03 | I32: km/kWh | J32: 69008 | K32: 1000 | L32: 2830 | M32: 2830 | N32: 0.8 | O32: 0.75 | P32: 35 | R32: 5696549 | S32: 5696549 | T32: 5696549 | U32: 5696549 | V32: 5696549 | W32: 5696549 | X32: 94402 | Y32: 94402 | Z32: 94402 | AA32: 94402 | AB32: 94402 | AC32: 94402 | AD32: rail_frgt | AE32: RFRGTICY | AF32: RFRGTLOC | AG32: tonnes
... A45: MOTOF_LPG | B45: MOTOF_CNG motorbikes_frgt vehicle | C45: LPG | D45: LPG | G45: 0.825 | H45: 1.115 | I45: MJ/km | J45: 35000 | K45: 1000 | L45: 1.76 | M45: 1.76 | N45: 0.4 | O45: 0.85 | P45: 10 | R45: 2592 | S45: 2592 | T45: 2592 | U45: 2592 | V45: 2592 | W45: 2592 | X45: 35 | Y45: 35 | Z45: 35 | AA45: 35 | AB45: 35 | AC45: 35 | AD45: motorbikes_frgt | AE45: MFRGTHWY | AF45: MFRGTCTY | AG45: tonnes

Sheet new-format
A1: name | B1: desc | C1: fuels | D1: primary_fuel | E1: blend_fuel | F1: blend_share_up | G1: vintage | H1: region | I1: year
A2: LDV_GSL | B2: Gasoline Light Duty Vehicle | C2: GSL | D2: GSL
A3: LDV_DSL | B3: Diesel Light Duty Vehicle | C3: DSL | D3: DSL
A4: LDV_E10 | B4: Gasoline–Ethanol Blend (E10) Light Duty Vehicle | C4: GSL|BIO | D4: GSL | E4: BIO | F4: 0.1
A5: LDV_E85 | B5: E85 Flex-Fuel Light Duty Vehicle (85% Ethanol) | C5: GSL|BIO | D5: BIO | E5: GSL | F5: 0.15 | G5: 2030 | H5: IND
H6: MH

Sheet fleet
A1: new | B1: region | C1: stock_2024 | D1: stock_2025 | E1: stock_2030 | F1: stock_2035 | G1: stock_2040 | H1: stock_2045 | I1: stock_2050 | J1: cap.lo | K1: cap.up | L1: cap.fx | M1: ncap.lo | N1: ncap.up | O1: ncap.fx | P1: notes | Q1: branch
A2: LDV_GSL | B2: IND | C2: 22948 | D2: 21513.8 | E2: 14342.5 | F2: 7171.2 | G2: 0 | H2: 0 | I2: 0 | P2: Stock from EPS SYVbT-passenger (2018 base) in 1000-vehicle units. NA techs (E10/E85/E100/B100/HYB) set to 0 — counted under GSL/DSL parent. Recalibrate for 2024 from MoRTH/VAHAN before use. | Q2: LDV_psgr
A3: LDV_DSL | B3: IND | C3: 7216.7 | D3: 6765.7 | E3: 4510.4 | F3: 2255.2 | G3: 0 | H3: 0 | I3: 0 | P3: Stock from EPS SYVbT-passenger (2018 base) in 1000-vehicle units. NA techs (E10/E85/E100/B100/HYB) set to 0 — counted under GSL/DSL parent. Recalibrate for 2024 from MoRTH/VAHAN before use. | Q3: LDV_psgr
A4: LDV_E10 | B4: IND | C4: 0 | P4: Stock from EPS SYVbT-passenger (2018 base) in 1000-vehicle units. NA techs (E10/E85/E100/B100/HYB) set to 0 — counted under GSL/DSL parent. Recalibrate for 2024 from MoRTH/VAHAN before use. | Q4: LDV_psgr
A5: LDV_E85 | B5: IND | C5: 0 | P5: Stock from EPS SYVbT-passenger (2018 base) in 1000-vehicle units. NA techs (E10/E85/E100/B100/HYB) set to 0 — counted under GSL/DSL parent. Recalibrate for 2024 from MoRTH/VAHAN before use. | Q5: LDV_psgr
A6: LDV_E100 | B6: IND | C6: 0 | P6: Stock from EPS SYVbT-passenger (2018 base) in 1000-vehicle units. NA techs (E10/E85/E100/B100/HYB) set to 0 — counted under GSL/DSL parent. Recalibrate for 2024 from MoRTH/VAHAN before use. | Q6: LDV_psgr
A7: LDV_B100 | B7: IND | C7: 0 | P7: Stock from EPS SYVbT-passenger (2018 base) in 1000-vehicle units. NA techs (E10/E85/E100/B100/HYB) set to 0 — counted under GSL/DSL parent. Recalibrate for 2024 from MoRTH/VAHAN before use. | Q7: LDV_psgr
A8: LDV_CNG | B8: IND | C8: 849.8 | D8: 796.7 | E8: 531.1 | F8: 265.6 | G8: 0 | H8: 0 | I8: 0 | P8: Stock from EPS SYVbT-passenger (2018 base) in 1000-vehicle units. NA techs (E10/E85/E100/B100/HYB) set to 0 — counted under GSL/DSL parent. Recalibrate for 2024 from MoRTH/VAHAN before use. | Q8: LDV_psgr
A9: LDV_LPG | B9: IND | C9: 849.8 | D9: 796.7 | E9: 531.1 | F9: 265.6 | G9: 0 | H9: 0 | I9: 0 | P9: Stock from EPS SYVbT-passenger (2018 base) in 1000-vehicle units. NA techs (E10/E85/E100/B100/HYB) set to 0 — counted under GSL/DSL parent. Recalibrate for 2024 from MoRTH/VAHAN before use. | Q9: LDV_psgr
A10: LDV_HYB | B10: IND | C10: 0 | P10: Stock from EPS SYVbT-passenger (2018 base) in 1000-vehicle units. NA techs (E10/E85/E100/B100/HYB) set to 0 — counted under GSL/DSL parent. Recalibrate for 2024 from MoRTH/VAHAN before use. | Q10: LDV_psgr
A11: LDV_PHEV | B11: IND | C11: 0 | P11: Stock from EPS SYVbT-passenger (2018 base) in 1000-vehicle units. NA techs (E10/E85/E100/B100/HYB) set to 0 — counted under GSL/DSL parent. Recalibrate for 2024 from MoRTH/VAHAN before use. | Q11: LDV_psgr
A12: LDV_BEV | B12: IND | C12: 615.8 | D12: 577.3 | E12: 384.9 | F12: 192.4 | G12: 0 | H12: 0 | I12: 0 | P12: Stock from EPS SYVbT-passenger (2018 base) in 1000-vehicle units. NA techs (E10/E85/E100/B100/HYB) set to 0 — counted under GSL/DSL parent. Recalibrate for 2024 from MoRTH/VAHAN before use. | Q12: LDV_psgr
A13: LDV_H2 | B13: IND | C13: 0 | P13: Stock from EPS SYVbT-passenger (2018 base) in 1000-vehicle units. NA techs (E10/E85/E100/B100/HYB) set to 0 — counted under GSL/DSL parent. Recalibrate for 2024 from MoRTH/VAHAN before use. | Q13: LDV_psgr
A14: LDVF_DSL | B14: IND | C14: 3091.9 | D14: 2782.7 | E14: 1236.8 | F14: 0 | G14: 0 | H14: 0 | I14: 0 | P14: Stock from EPS SYVbT-freight (2018 base) LDVs row. 1000-vehicle units. | Q14: LDV_frgt
A15: LDVF_CNG | B15: IND | C15: 0 | P15: Stock from EPS SYVbT-freight (2018 base) LDVs row. 1000-vehicle units. | Q15: LDV_frgt
A16: LDVF_BEV | B16: IND | C16: 0 | P16: Stock from EPS SYVbT-freight (2018 base) LDVs row. 1000-vehicle units. | Q16: LDV_frgt
A17: HDV_DSL | B17: IND | C17: 1928.8 | D17: 1735.9 | E17: 771.5 | F17: 0 | G17: 0 | H17: 0 | I17: 0 | P17: Stock from EPS SYVbT-passenger (2018 base) HDVs row. 1000-vehicle units. | Q17: HDV_psgr
A18: HDV_CNG | B18: IND | C18: 26.7 | D18: 24 | E18: 10.7 | F18: 0 | G18: 0 | H18: 0 | I18: 0 | P18: Stock from EPS SYVbT-passenger (2018 base) HDVs row. 1000-vehicle units. | Q18: HDV_psgr
A19: HDV_BEV | B19: IND | C19: 8.4 | D19: 7.6 | E19: 3.4 | F19: 0 | G19: 0 | H19: 0 | I19: 0 | P19: Stock from EPS SYVbT-passenger (2018 base) HDVs row. 1000-vehicle units. | Q19: HDV_psgr
A20: HDVF_DSL | B20: IND | C20: 6177.5 | D20: 5559.8 | E20: 2471 | F20: 0 | G20: 0 | H20: 0 | I20: 0 | P20: Stock from EPS SYVbT-freight (2018 base) HDVs row. 1000-vehicle units. | Q20: HDV_frgt
A21: HDVF_CNG | B21: IND | C21: 0 | P21: Stock from EPS SYVbT-freight (2018 base) HDVs row. 1000-vehicle units. | Q21: HDV_frgt
A22: HDVF_BEV | B22: IND | C22: 0 | P22: Stock from EPS SYVbT-freight (2018 base) HDVs row. 1000-vehicle units. | Q22: HDV_frgt
A23: ARC_DSL | B23: IND | C23: 0.6 | D23: 0.6 | E23: 0.4 | F23: 0.3 | G23: 0.1 | H23: 0 | I23: 0 | P23: Stock from EPS SYVbT-passenger (2018 base) aircraft row. 1000-vehicle units. | Q23: aircraft_psgr
A24: ARC_BEV | B24: IND | C24: 0 | P24: Stock from EPS SYVbT-passenger (2018 base) aircraft row. 1000-vehicle units. | Q24: aircraft_psgr
A25: ARC_H2 | B25: IND | C25: 0 | P25: Stock from EPS SYVbT-passenger (2018 base) aircraft row. 1000-vehicle units. | Q25: aircraft_psgr
A26: ARCF_DSL | B26: IND | C26: 0.1 | D26: 0.1 | E26: 0.1 | F26: 0.1 | G26: 0 | H26: 0 | I26: 0 | P26: Stock from EPS SYVbT-freight (2018 base) aircraft row. 1000-vehicle units. | Q26: aircraft_frgt
A27: ARCF_BEV | B27: IND | C27: 0 | P27: Stock from EPS SYVbT-freight (2018 base) aircraft row. 1000-vehicle units. | Q27: aircraft_frgt
A28: ARCF_H2 | B28: IND | C28: 0 | P28: Stock from EPS SYVbT-freight (2018 base) aircraft row. 1000-vehicle units. | Q28: aircraft_frgt
A29: RAIL_BEV | B29: IND | C29: 3.2 | D29: 3.1 | E29: 2.7 | F29: 2.2 | G29: 1.7 | H29: 1.3 | I29: 0.8 | P29: Stock from EPS SYVbT-passenger (2018 base) rail row. 1000-vehicle units. | Q29: rail_psgr
A30: RAIL_DSL | B30: IND | C30: 3.1 | D30: 3 | E30: 2.6 | F30: 2.1 | G30: 1.7 | H30: 1.2 | I30: 0.8 | P30: Stock from EPS SYVbT-passenger (2018 base) rail row. 1000-vehicle units. | Q30: rail_psgr
A31: RAIL_H2 | B31: IND | C31: 0 | P31: Stock from EPS SYVbT-passenger (2018 base) rail row. 1000-vehicle units. | Q31: rail_psgr
A32: RAILF_BEV | B32: IND | C32: 3.6 | D32: 3.5 | E32: 3 | F32: 2.5 | G32: 2 | H32: 1.4 | I32: 0.9 | P32: Stock from EPS SYVbT-freight (2018 base) rail row. 1000-vehicle units. | Q32: rail_frgt
A33: RAILF_DSL | B33: IND | C33: 1.8 | D33: 1.7 | E33: 1.5 | F33: 1.2 | G33: 1 | H33: 0.7 | I33: 0.5 | P33: Stock from EPS SYVbT-freight (2018 base) rail row. 1000-vehicle units. | Q33: rail_frgt
A34: RAILF_H2 | B34: IND | C34: 0 | P34: Stock from EPS SYVbT-freight (2018 base) rail row. 1000-vehicle units. | Q34: rail_frgt
A35: SHIP_DSL | B35: IND | C35: 0.1 | D35: 0.1 | E35: 0.1 | F35: 0.1 | G35: 0.1 | H35: 0 | I35: 0 | P35: Stock from EPS SYVbT-passenger (2018 base) ships row. 1000-vehicle units. | Q35: ships_psgr
A36: SHIP_H2 | B36: IND | C36: 0 | P36: Stock from EPS SYVbT-passenger (2018 base) ships row. 1000-vehicle units. | Q36: ships_psgr
A37: SHIPF_DSL | B37: IND | C37: 1.2 | D37: 1.2 | E37: 1 | F37: 0.8 | G37: 0.6 | H37: 0.4 | I37: 0.3 | P37: Stock from EPS SYVbT-freight (2018 base) ships row. 1000-vehicle units. | Q37: ships_frgt
A38: SHIPF_H2 | B38: IND | C38: 0 | P38: Stock from EPS SYVbT-freight (2018 base) ships row. 1000-vehicle units. | Q38: ships_frgt
A39: MOTO_GSL | B39: IND | C39: 181871.8 | D39: 163684.6 | E39: 72748.7 | F39: 0 | G39: 0 | H39: 0 | I39: 0 | P39: Stock from EPS SYVbT-passenger (2018 base) motorbikes row. 1000-vehicle units. | Q39: motorbikes_psgr
A40: MOTO_BEV | B40: IND | C40: 7487.2 | D40: 6738.5 | E40: 2994.9 | F40: 0 | G40: 0 | H40: 0 | I40: 0 | P40: Stock from EPS SYVbT-passenger (2018 base) motorbikes row. 1000-vehicle units. | Q40: motorbikes_psgr
...

Sheet fleet_new
A1: Vehicle fleet data
A2: 1. Based on average vehicle lifetimes, registration data was obtained from VAHAN.
A3: 2. For cars average life=15 years, for all other=10 years
A4: 3. diff fuel categorisations have been clubbed together based on structure of IDEEA (kindly refer to the note below the table)
A7: VEHICLE CATEGORY | B7: E20| GSL | C7: DSL | D7: CNG | E7: LPG | F7: HYB | G7: PHEV | H7: BEV | I7: H2 | J7: OTHERS
A8: HEAVY GOODS VEHICLE | B8: 218 | C8: 2569539 | D8: 43296 | E8: 15 | F8: 1 | G8: 0 | H8: 1170 | I8: 1 | J8: 9481
A9: HEAVY PASSENGER VEHICLE | B9: 80 | C9: 234154 | D9: 16356 | E9: 4 | F9: 0 | G9: 0 | H9: 14922 | I9: 15 | J9: 148
A10: LIGHT GOODS VEHICLE (4W_freight) | B10: 256097 | C10: 4904678 | D10: 483532 | E10: 1786 | F10: 69 | G10: 0 | H10: 22925 | I10: 0 | J10: 260692
A11: MEDIUM GOODS VEHICLE | B11: 35 | C11: 330918 | D11: 52724 | E11: 0 | F11: 0 | G11: 0 | H11: 8 | I11: 0 | J11: 5220
A12: MEDIUM PASSENGER VEHICLE | B12: 99 | C12: 200071 | D12: 16619 | E12: 2 | F12: 0 | G12: 0 | H12: 875 | I12: 5 | J12: 25
A13: TWO-WHEELER | B13: 175483957 | C13: 6401 | D13: 84038 | E13: 1091 | F13: 18 | G13: 0 | H13: 4366428 | I13: 0 | J13: 40383
A14: LIGHT DUTY VEHICLE | B14: 24876709 | C14: 15203904 | D14: 4983997 | E14: 430570 | F14: 1504261 | G14: 114 | H14: 457354 | I14: 1 | J14: 77881
A15: E-RICKSHAW(P) | B15: 36 | C15: 613 | D15: 94 | E15: 979 | F15: 0 | G15: 0 | H15: 2320510 | I15: 0 | J15: 2664
A16: THREE WHEELER (GOODS) | B16: 4595 | C16: 842236 | D16: 160491 | E16: 473 | F16: 0 | G16: 0 | H16: 110583 | I16: 0 | J16: 374
A17: THREE WHEELER (PASSENGER) | B17: 143979 | C17: 1410671 | D17: 1967843 | E17: 562603 | F17: 6 | G17: 0 | H17: 403346 | I17: 0 | J17: 6944
A19: Note:
A20: 1. Diesel hybrids are included with diesel while petrol hybrid is a separate category
A21: 2. All gasoline vehicles are considered E20|GSL from 2025 onwards
A22: 3. CNG includes CNG+Petrol/CNG
A23: 4. LPG includes LPG+PETROL/LPG
A25: Shares
A26: VEHICLE CATEGORY | B26: E20| GSL | C26: DSL | D26: CNG | E26: LPG | F26: HYB | G26: PHEV | H26: BEV | I26: H2 | J26: OTHERS
A27: HEAVY GOODS VEHICLE | B27: 0 | C27: 0.98 | D27: 0.02 | E27: 0 | F27: 0 | G27: 0 | H27: 0 | I27: 0 | J27: 0
A28: HEAVY PASSENGER VEHICLE | B28: 0 | C28: 0.88 | D28: 0.06 | E28: 0 | F28: 0 | G28: 0 | H28: 0.06 | I28: 0 | J28: 0
A29: LIGHT GOODS VEHICLE | B29: 0.04 | C29: 0.83 | D29: 0.08 | E29: 0 | F29: 0 | G29: 0 | H29: 0 | I29: 0 | J29: 0.04
A30: MEDIUM GOODS VEHICLE | B30: 0 | C30: 0.85 | D30: 0.14 | E30: 0 | F30: 0 | G30: 0 | H30: 0 | I30: 0 | J30: 0.01
A31: MEDIUM PASSENGER VEHICLE | B31: 0 | C31: 0.92 | D31: 0.08 | E31: 0 | F31: 0 | G31: 0 | H31: 0 | I31: 0 | J31: 0
A32: TWO-WHEELER | B32: 0.98 | C32: 0 | D32: 0 | E32: 0 | F32: 0 | G32: 0 | H32: 0.02 | I32: 0 | J32: 0
A33: LIGHT DUTY VEHICLE | B33: 0.52 | C33: 0.32 | D33: 0.1 | E33: 0.01 | F33: 0.03 | G33: 0 | H33: 0.01 | I33: 0 | J33: 0
A34: E-RICKSHAW(P) | B34: 0 | C34: 0 | D34: 0 | E34: 0 | F34: 0 | G34: 0 | H34: 1 | I34: 0 | J34: 0
A35: THREE WHEELER (GOODS) | B35: 0 | C35: 0.75 | D35: 0.14 | E35: 0 | F35: 0 | G35: 0 | H35: 0.1 | I35: 0 | J35: 0
A36: THREE WHEELER (PASSENGER) | B36: 0.03 | C36: 0.31 | D36: 0.44 | E36: 0.13 | F36: 0 | G36: 0 | H36: 0.09 | I36: 0 | J36: 0

Sheet constraints
A1: name | B1: desc | C1: type | D1: tech | E1: commodity | F1: region | G1: y2025 | H1: y2030 | I1: y2035 | J1: y2040 | K1: y2045 | L1: y2050 | M1: notes
A2: E10_MANDATE | B2: Minimum ethanol blend share in GSL fleet vehicles (E10 mandate, 10%) | C2: share.lo | E2: BIO | F2: IND | M2: Value = min BIO share [0-1] in total GSL input by year (e.g. 0.10)
A3: E20_MANDATE | B3: Minimum ethanol blend share in GSL fleet vehicles (E20 mandate, 20%) | C3: share.lo | E3: BIO | F3: IND | M3: Value = min BIO share [0-1] in total GSL input by year (e.g. 0.20)
A4: EV_NCAP_MIN | B4: Minimum new EV capacity additions per year (EV mandate) | C4: ncap.lo | D4: LDV_BEV | F4: IND | M4: Value = min new 1000-vehicle units/year for LDV_BEV
A5: CO2_CAP_TRANSPORT | B5: Maximum CO2 emissions from LDV transport sector per year | C5: emission_cap | E5: CO2 | F5: IND | M5: Value = max MtCO2/year from LDV transport
